<?xml version="1.0" encoding="utf-8"?>
<!-- =================================================================================== -->
<!-- |    This document was autogenerated by xacro from mrobot_with_arm_and_laser.urdf.xacro | -->
<!-- |    EDITING THIS FILE BY HAND IS NOT RECOMMENDED                                 | -->
<!-- =================================================================================== -->
<robot name="mrobot">
  <!-- Defining the colors used in this robot -->
  <material name="Black">
    <color rgba="0 0 0 1"/>
  </material>
  <material name="White">
    <color rgba="1 1 1 1"/>
  </material>
  <material name="Blue">
    <color rgba="0 0 1 1"/>
  </material>
  <material name="Red">
    <color rgba="1 0 0 1"/>
  </material>
  <material name="Green">
    <color rgba="0.0 0.8 0.0 1.0"/>
  </material>
  <material name="yellow">
    <color rgba="1 0.4 0 1"/>
  </material>
  <material name="black">
    <color rgba="0 0 0 0.95"/>
  </material>
  <material name="gray">
    <color rgba="0.75 0.75 0.75 1"/>
  </material>
  <link name="base_footprint">
    <visual>
      <origin rpy="0 0 0" xyz="0 0 0"/>
      <geometry>
        <box size="0.001 0.001 0.001"/>
      </geometry>
    </visual>
  </link>
  <link name="base_link">
    <inertial>
      <mass value="2"/>
      <origin xyz="0 0 0.0"/>
      <inertia ixx="0.01" ixy="0.0" ixz="0.0" iyy="0.01" iyz="0.0" izz="0.5"/>
    </inertial>
    <visual>
      <origin rpy="0 0 0" xyz=" 0 0 0"/>
      <geometry>
        <cylinder length="0.005" radius="0.13"/>
      </geometry>
      <material name="yellow"/>
    </visual>
    <collision>
      <origin rpy="0 0 0" xyz="0 0 0"/>
      <geometry>
        <cylinder length="0.005" radius="0.13"/>
      </geometry>
    </collision>
  </link>
  <joint name="base_footprint_joint" type="fixed">
    <origin rpy="0 0 0" xyz="0 0 0.033"/>
    <parent link="base_footprint"/>
    <child link="base_link"/>
  </joint>
  <link name="left_motor">
    <inertial>
      <origin xyz="0.0 0 0"/>
      <mass value="0.1"/>
      <inertia ixx="0.001" ixy="0.0" ixz="0.0" iyy="0.001" iyz="0.0" izz="0.001"/>
    </inertial>
    <visual>
      <origin rpy="1.570795 0 0" xyz="0 0 0"/>
      <geometry>
        <cylinder length="0.08" radius="0.02"/>
      </geometry>
      <material name="gray"/>
    </visual>
    <collision>
      <origin rpy="1.570795 0 0" xyz="0 0 0"/>
      <geometry>
        <cylinder length="0.08" radius="0.02"/>
      </geometry>
    </collision>
  </link>
  <joint name="base_left_motor_joint" type="fixed">
    <origin rpy="0 0 0" xyz="-0.055 0.075 0"/>
    <parent link="base_link"/>
    <child link="left_motor"/>
  </joint>
  <link name="left_wheel_link">
    <inertial>
      <origin xyz="0 0 0"/>
      <mass value="0.01"/>
      <inertia ixx="0.001" ixy="0.0" ixz="0.0" iyy="0.001" iyz="0.0" izz="0.001"/>
    </inertial>
    <visual>
      <origin rpy="1.570795 0 0" xyz="0 0 0"/>
      <geometry>
        <cylinder length="0.017" radius="0.033"/>
      </geometry>
      <material name="white">
        <color rgba="1 1 1 0.9"/>
      </material>
    </visual>
    <collision>
      <origin rpy="1.570795 0 0" xyz="0 0 0"/>
      <geometry>
        <cylinder length="0.017" radius="0.033"/>
      </geometry>
    </collision>
  </link>
  <joint name="left_wheel_joint" type="continuous">
    <origin rpy="0 0 0" xyz="0 0.0485 0"/>
    <parent link="left_motor"/>
    <child link="left_wheel_link"/>
    <axis xyz="0 1 0"/>
  </joint>
  <link name="right_motor">
    <inertial>
      <origin xyz="0.0 0 0"/>
      <mass value="0.1"/>
      <inertia ixx="0.001" ixy="0.0" ixz="0.0" iyy="0.001" iyz="0.0" izz="0.001"/>
    </inertial>
    <visual>
      <origin rpy="1.570795 0 0" xyz="0 0 0"/>
      <geometry>
        <cylinder length="0.08" radius="0.02"/>
      </geometry>
      <material name="gray"/>
    </visual>
    <collision>
      <origin rpy="1.570795 0 0" xyz="0 0 0"/>
      <geometry>
        <cylinder length="0.08" radius="0.02"/>
      </geometry>
    </collision>
  </link>
  <joint name="base_right_motor_joint" type="fixed">
    <origin rpy="0 0 0" xyz="-0.055 -0.075 0"/>
    <parent link="base_link"/>
    <child link="right_motor"/>
  </joint>
  <link name="right_wheel_link">
    <inertial>
      <origin xyz="0 0 0"/>
      <mass value="0.01"/>
      <inertia ixx="0.001" ixy="0.0" ixz="0.0" iyy="0.001" iyz="0.0" izz="0.001"/>
    </inertial>
    <visual>
      <origin rpy="1.570795 0 0" xyz="0 0 0"/>
      <geometry>
        <cylinder length="0.017" radius="0.033"/>
      </geometry>
      <material name="white">
        <color rgba="1 1 1 0.9"/>
      </material>
    </visual>
    <collision>
      <origin rpy="1.570795 0 0" xyz="0 0 0"/>
      <geometry>
        <cylinder length="0.017" radius="0.033"/>
      </geometry>
    </collision>
  </link>
  <joint name="right_wheel_joint" type="continuous">
    <origin rpy="0 0 0" xyz="0 -0.0485 0"/>
    <parent link="right_motor"/>
    <child link="right_wheel_link"/>
    <axis xyz="0 1 0"/>
  </joint>
  <link name="front_caster_link">
    <inertial>
      <origin xyz="0 0 0"/>
      <mass value="0.001"/>
      <inertia ixx="0.0001" ixy="0.0" ixz="0.0" iyy="0.0001" iyz="0.0" izz="0.0001"/>
    </inertial>
    <visual>
      <origin rpy="1.570795 0 0" xyz="0 0 0"/>
      <geometry>
        <sphere radius="0.0165"/>
      </geometry>
      <material name="black"/>
    </visual>
    <collision>
      <origin rpy="1.570795 0 0" xyz="0 0 0.01"/>
      <geometry>
        <sphere radius="0.0165"/>
      </geometry>
    </collision>
  </link>
  <joint name="front_caster_joint" type="fixed">
    <origin rpy="0 0 0" xyz="0.1135 0 -0.0165"/>
    <parent link="base_link"/>
    <child link="front_caster_link"/>
  </joint>
  <joint name="standoff_2in_1_joint" type="fixed">
    <origin rpy="0 0 0" xyz="-0.09 -0.07 0.035"/>
    <parent link="base_link"/>
    <child link="standoff_2in_1_link"/>
  </joint>
  <link name="standoff_2in_1_link">
    <inertial>
      <mass value="0.001"/>
      <origin xyz="0 0 0"/>
      <inertia ixx="0.0001" ixy="0.0" ixz="0.0" iyy="0.0001" iyz="0.0" izz="0.0001"/>
    </inertial>
    <visual>
      <origin rpy="0 0 0" xyz=" 0 0 0 "/>
      <geometry>
        <box size="0.01 0.01 0.07"/>
      </geometry>
      <material name="black">
        <color rgba="0.16 0.17 0.15 0.9"/>
      </material>
    </visual>
    <collision>
      <origin rpy="0 0 0" xyz="0.0 0.0 0.0"/>
      <geometry>
        <box size="0.01 0.01 0.07"/>
      </geometry>
    </collision>
  </link>
  <joint name="standoff_2in_2_joint" type="fixed">
    <origin rpy="0 0 0" xyz="-0.09 0.07 0.035"/>
    <parent link="base_link"/>
    <child link="standoff_2in_2_link"/>
  </joint>
  <link name="standoff_2in_2_link">
    <inertial>
      <mass value="0.001"/>
      <origin xyz="0 0 0"/>
      <inertia ixx="0.0001" ixy="0.0" ixz="0.0" iyy="0.0001" iyz="0.0" izz="0.0001"/>
    </inertial>
    <visual>
      <origin rpy="0 0 0" xyz=" 0 0 0 "/>
      <geometry>
        <box size="0.01 0.01 0.07"/>
      </geometry>
      <material name="black">
        <color rgba="0.16 0.17 0.15 0.9"/>
      </material>
    </visual>
    <collision>
      <origin rpy="0 0 0" xyz="0.0 0.0 0.0"/>
      <geometry>
        <box size="0.01 0.01 0.07"/>
      </geometry>
    </collision>
  </link>
  <joint name="standoff_2in_3_joint" type="fixed">
    <origin rpy="0 0 0" xyz="0.06 -0.1 0.035"/>
    <parent link="base_link"/>
    <child link="standoff_2in_3_link"/>
  </joint>
  <link name="standoff_2in_3_link">
    <inertial>
      <mass value="0.001"/>
      <origin xyz="0 0 0"/>
      <inertia ixx="0.0001" ixy="0.0" ixz="0.0" iyy="0.0001" iyz="0.0" izz="0.0001"/>
    </inertial>
    <visual>
      <origin rpy="0 0 0" xyz=" 0 0 0 "/>
      <geometry>
        <box size="0.01 0.01 0.07"/>
      </geometry>
      <material name="black">
        <color rgba="0.16 0.17 0.15 0.9"/>
      </material>
    </visual>
    <collision>
      <origin rpy="0 0 0" xyz="0.0 0.0 0.0"/>
      <geometry>
        <box size="0.01 0.01 0.07"/>
      </geometry>
    </collision>
  </link>
  <joint name="standoff_2in_4_joint" type="fixed">
    <origin rpy="0 0 0" xyz="0.06 0.1 0.035"/>
    <parent link="base_link"/>
    <child link="standoff_2in_4_link"/>
  </joint>
  <link name="standoff_2in_4_link">
    <inertial>
      <mass value="0.001"/>
      <origin xyz="0 0 0"/>
      <inertia ixx="0.0001" ixy="0.0" ixz="0.0" iyy="0.0001" iyz="0.0" izz="0.0001"/>
    </inertial>
    <visual>
      <origin rpy="0 0 0" xyz=" 0 0 0 "/>
      <geometry>
        <box size="0.01 0.01 0.07"/>
      </geometry>
      <material name="black">
        <color rgba="0.16 0.17 0.15 0.9"/>
      </material>
    </visual>
    <collision>
      <origin rpy="0 0 0" xyz="0.0 0.0 0.0"/>
      <geometry>
        <box size="0.01 0.01 0.07"/>
      </geometry>
    </collision>
  </link>
  <joint name="plate_1_joint" type="fixed">
    <origin rpy="0 0 0" xyz="0 0 0.07"/>
    <parent link="base_link"/>
    <child link="plate_1_link"/>
  </joint>
  <link name="plate_1_link">
    <inertial>
      <mass value="0.1"/>
      <origin xyz="0 0 0"/>
      <inertia ixx="0.01" ixy="0.0" ixz="0.0" iyy="0.01" iyz="0.0" izz="0.01"/>
    </inertial>
    <visual>
      <origin rpy="0 0 0" xyz=" 0 0 0 "/>
      <geometry>
        <cylinder length="0.005" radius="0.13"/>
      </geometry>
      <material name="yellow"/>
    </visual>
    <collision>
      <origin rpy="0 0 0" xyz="0.0 0.0 0.0"/>
      <geometry>
        <cylinder length="0.005" radius="0.13"/>
      </geometry>
    </collision>
  </link>
  <joint name="standoff_2in_5_joint" type="fixed">
    <origin rpy="0 0 0" xyz="0 0 0.07"/>
    <parent link="standoff_2in_1_link"/>
    <child link="standoff_2in_5_link"/>
  </joint>
  <link name="standoff_2in_5_link">
    <inertial>
      <mass value="0.001"/>
      <origin xyz="0 0 0"/>
      <inertia ixx="0.0001" ixy="0.0" ixz="0.0" iyy="0.0001" iyz="0.0" izz="0.0001"/>
    </inertial>
    <visual>
      <origin rpy="0 0 0" xyz=" 0 0 0 "/>
      <geometry>
        <box size="0.01 0.01 0.07"/>
      </geometry>
      <material name="black">
        <color rgba="0.16 0.17 0.15 0.9"/>
      </material>
    </visual>
    <collision>
      <origin rpy="0 0 0" xyz="0.0 0.0 0.0"/>
      <geometry>
        <box size="0.01 0.01 0.07"/>
      </geometry>
    </collision>
  </link>
  <joint name="standoff_2in_6_joint" type="fixed">
    <origin rpy="0 0 0" xyz="0 0 0.07"/>
    <parent link="standoff_2in_2_link"/>
    <child link="standoff_2in_6_link"/>
  </joint>
  <link name="standoff_2in_6_link">
    <inertial>
      <mass value="0.001"/>
      <origin xyz="0 0 0"/>
      <inertia ixx="0.0001" ixy="0.0" ixz="0.0" iyy="0.0001" iyz="0.0" izz="0.0001"/>
    </inertial>
    <visual>
      <origin rpy="0 0 0" xyz=" 0 0 0 "/>
      <geometry>
        <box size="0.01 0.01 0.07"/>
      </geometry>
      <material name="black">
        <color rgba="0.16 0.17 0.15 0.9"/>
      </material>
    </visual>
    <collision>
      <origin rpy="0 0 0" xyz="0.0 0.0 0.0"/>
      <geometry>
        <box size="0.01 0.01 0.07"/>
      </geometry>
    </collision>
  </link>
  <joint name="standoff_2in_7_joint" type="fixed">
    <origin rpy="0 0 0" xyz="0 0 0.07"/>
    <parent link="standoff_2in_3_link"/>
    <child link="standoff_2in_7_link"/>
  </joint>
  <link name="standoff_2in_7_link">
    <inertial>
      <mass value="0.001"/>
      <origin xyz="0 0 0"/>
      <inertia ixx="0.0001" ixy="0.0" ixz="0.0" iyy="0.0001" iyz="0.0" izz="0.0001"/>
    </inertial>
    <visual>
      <origin rpy="0 0 0" xyz=" 0 0 0 "/>
      <geometry>
        <box size="0.01 0.01 0.07"/>
      </geometry>
      <material name="black">
        <color rgba="0.16 0.17 0.15 0.9"/>
      </material>
    </visual>
    <collision>
      <origin rpy="0 0 0" xyz="0.0 0.0 0.0"/>
      <geometry>
        <box size="0.01 0.01 0.07"/>
      </geometry>
    </collision>
  </link>
  <joint name="standoff_2in_8_joint" type="fixed">
    <origin rpy="0 0 0" xyz="0 0 0.07"/>
    <parent link="standoff_2in_4_link"/>
    <child link="standoff_2in_8_link"/>
  </joint>
  <link name="standoff_2in_8_link">
    <inertial>
      <mass value="0.001"/>
      <origin xyz="0 0 0"/>
      <inertia ixx="0.0001" ixy="0.0" ixz="0.0" iyy="0.0001" iyz="0.0" izz="0.0001"/>
    </inertial>
    <visual>
      <origin rpy="0 0 0" xyz=" 0 0 0 "/>
      <geometry>
        <box size="0.01 0.01 0.07"/>
      </geometry>
      <material name="black">
        <color rgba="0.16 0.17 0.15 0.9"/>
      </material>
    </visual>
    <collision>
      <origin rpy="0 0 0" xyz="0.0 0.0 0.0"/>
      <geometry>
        <box size="0.01 0.01 0.07"/>
      </geometry>
    </collision>
  </link>
  <joint name="plate_2_joint" type="fixed">
    <origin rpy="0 0 0" xyz="0 0 0.07"/>
    <parent link="plate_1_link"/>
    <child link="plate_2_link"/>
  </joint>
  <link name="plate_2_link">
    <inertial>
      <mass value="0.01"/>
      <origin xyz="0 0 0"/>
      <inertia ixx="0.001" ixy="0.0" ixz="0.0" iyy="0.001" iyz="0.0" izz="0.001"/>
    </inertial>
    <visual>
      <origin rpy="0 0 0" xyz=" 0 0 0 "/>
      <geometry>
        <cylinder length="0.005" radius="0.13"/>
      </geometry>
      <material name="yellow"/>
    </visual>
    <collision>
      <origin rpy="0 0 0" xyz="0.0 0.0 0.0"/>
      <geometry>
        <cylinder length="0.005" radius="0.13"/>
      </geometry>
    </collision>
  </link>
  <!-- rplidar -->
  <joint name="rplidar_joint" type="fixed">
    <origin rpy="0 0 0" xyz="0 0 0.028"/>
    <parent link="plate_1_link"/>
    <child link="laser_link"/>
  </joint>
  <link name="laser_link">
    <inertial>
      <mass value="0.1"/>
      <origin xyz="0 0 0"/>
      <inertia ixx="0.01" ixy="0.0" ixz="0.0" iyy="0.01" iyz="0.0" izz="0.01"/>
    </inertial>
    <visual>
      <origin rpy="0 0 0" xyz=" 0 0 0 "/>
      <geometry>
        <cylinder length="0.05" radius="0.05"/>
      </geometry>
      <material name="black"/>
    </visual>
    <collision>
      <origin rpy="0 0 0" xyz="0.0 0.0 0.0"/>
      <geometry>
        <cylinder length="0.06" radius="0.05"/>
      </geometry>
    </collision>
  </link>
  <!-- arm -->
  <joint name="arm_joint" type="fixed">
    <origin rpy="0 0 0" xyz="0 0 0.02"/>
    <parent link="plate_2_link"/>
    <child link="base_link_of_arm"/>
  </joint>
  <!-- ///////////////////////////////////////   bottom_joint   ////////////////////////////////////////// -->
  <!--joint name="bottom_joint" type="fixed">
        <origin xyz="0 0 0" rpy="0 0 0" />
        <parent link="base_link_of_arm"/>
        <child link="bottom_link"/>
    </joint>
    <link name="bottom_link">
        <visual>
              <origin xyz=" 0 0 -0.02"  rpy="0 0 0"/>
                  <geometry>
                       <box size="1 1 0.02" />
                  </geometry>
              <material name="Brown" />
        </visual>
        <collision>
            <origin xyz=" 0 0 -0.02"  rpy="0 0 0"/>
            <geometry>
                <box size="1 1 0.02" />
            </geometry>
        </collision>
        <xacro:inertial_matrix mass="500"/>
    </link-->
  <!-- /////////////////////////////////////   BASE LINK    ////////////////////////////////////////////// -->
  <link name="base_link_of_arm">
    <visual>
      <origin rpy="0 0 0" xyz="0 0 0"/>
      <geometry>
        <box size="0.1 0.1 0.04"/>
      </geometry>
      <material name="White"/>
    </visual>
    <collision>
      <origin rpy="0 0 0" xyz="0 0 0"/>
      <geometry>
        <box size="0.1 0.1 0.04"/>
      </geometry>
    </collision>
    <inertial>
      <mass value="1"/>
      <inertia ixx="1.0" ixy="0.0" ixz="0.0" iyy="0.5" iyz="0.0" izz="1.0"/>
    </inertial>
  </link>
  <joint name="joint1" type="revolute">
    <parent link="base_link_of_arm"/>
    <child link="link1"/>
    <origin rpy="0 1.570795 0" xyz="0 0 0.02"/>
    <axis xyz="-1 0 0"/>
    <limit effort="300" lower="-2.96" upper="2.96" velocity="1"/>
    <dynamics damping="50" friction="1"/>
  </joint>
  <!-- /////////////////////////////////////   LINK1  ////////////////////////////////////////////// -->
  <link name="link1">
    <visual>
      <origin rpy="0 1.570795 0" xyz="-0.05 0 0"/>
      <geometry>
        <cylinder length="0.1" radius="0.03"/>
      </geometry>
      <material name="Blue"/>
    </visual>
    <collision>
      <origin rpy="0 1.570795 0" xyz="-0.05 0 0"/>
      <geometry>
        <cylinder length="0.1" radius="0.03"/>
      </geometry>
    </collision>
    <inertial>
      <mass value="1"/>
      <inertia ixx="1.0" ixy="0.0" ixz="0.0" iyy="0.5" iyz="0.0" izz="1.0"/>
    </inertial>
  </link>
  <joint name="joint2" type="revolute">
    <parent link="link1"/>
    <child link="link2"/>
    <origin rpy="-1.570795 0 1.570795" xyz="-0.1 0 0.0"/>
    <axis xyz="1 0 0"/>
    <limit effort="300" lower="-2.35" upper="2.35" velocity="1"/>
    <dynamics damping="50" friction="1"/>
  </joint>
  <!-- ///////////////////////////////////////   LINK2  ////////////////////////////////////////////// -->
  <link name="link2">
    <visual>
      <origin rpy="0 0 0" xyz="0 0 0.07"/>
      <geometry>
        <cylinder length="0.14" radius="0.03"/>
      </geometry>
      <material name="White"/>
    </visual>
    <collision>
      <origin rpy="0 0 0" xyz="0 0 0.07"/>
      <geometry>
        <cylinder length="0.14" radius="0.03"/>
      </geometry>
    </collision>
    <inertial>
      <mass value="1"/>
      <inertia ixx="1.0" ixy="0.0" ixz="0.0" iyy="0.5" iyz="0.0" izz="1.0"/>
    </inertial>
  </link>
  <joint name="joint3" type="revolute">
    <parent link="link2"/>
    <child link="link3"/>
    <origin rpy="0 3.14159 0" xyz="0 0 0.14"/>
    <axis xyz="-1 0 0"/>
    <limit effort="300" lower="-2.62" upper="2.62" velocity="1"/>
    <dynamics damping="50" friction="1"/>
  </joint>
  <!-- /////////////////////////////////   LINK3  ///////////////////////////////////////////////////// -->
  <link name="link3">
    <visual>
      <origin rpy="0 0 0" xyz="0 0 -0.11"/>
      <geometry>
        <cylinder length="0.22" radius="0.03"/>
      </geometry>
      <material name="Blue"/>
    </visual>
    <collision>
      <origin rpy="0 0 0" xyz="0 0 -0.11"/>
      <geometry>
        <cylinder length="0.22" radius="0.03"/>
      </geometry>
    </collision>
    <inertial>
      <mass value="1"/>
      <inertia ixx="1.0" ixy="0.0" ixz="0.0" iyy="0.5" iyz="0.0" izz="1.0"/>
    </inertial>
  </link>
  <joint name="joint4" type="revolute">
    <parent link="link3"/>
    <child link="link4"/>
    <origin rpy="0 1.570795 3.14159" xyz="0.0 0.0 -0.22"/>
    <axis xyz="1 0 0"/>
    <limit effort="300" lower="-2.62" upper="2.62" velocity="1"/>
    <dynamics damping="50" friction="1"/>
  </joint>
  <!-- ///////////////////////////////////   LINK4  //////////////////////////////////////////////// -->
  <link name="link4">
    <visual>
      <origin rpy="0 1.570795 0" xyz="0.03 0 0"/>
      <geometry>
        <cylinder length="0.06" radius="0.025"/>
      </geometry>
      <material name="Black"/>
    </visual>
    <collision>
      <origin rpy="0 1.570795 0" xyz="0.03 0 0"/>
      <geometry>
        <cylinder length="0.06" radius="0.025"/>
      </geometry>
    </collision>
    <inertial>
      <mass value="1"/>
      <inertia ixx="1.0" ixy="0.0" ixz="0.0" iyy="0.5" iyz="0.0" izz="1.0"/>
    </inertial>
  </link>
  <joint name="joint5" type="revolute">
    <parent link="link4"/>
    <child link="link5"/>
    <origin rpy="0 1.570795 0" xyz="0.06 0.0 0.0"/>
    <axis xyz="1 0 0"/>
    <limit effort="300" lower="-2.62" upper="2.62" velocity="1"/>
    <dynamics damping="50" friction="1"/>
  </joint>
  <!-- //////////////////////////////////   LINK5  ///////////////////////////////////////////////// -->
  <link name="link5">
    <visual>
      <origin rpy="0 0 0" xyz="0 0 0.03"/>
      <geometry>
        <cylinder length="0.06" radius="0.03"/>
      </geometry>
      <material name="White"/>
    </visual>
    <collision>
      <origin rpy="0 0 0" xyz="0 0 0.03 "/>
      <geometry>
        <cylinder length="0.06" radius="0.03"/>
      </geometry>
    </collision>
    <inertial>
      <mass value="1"/>
      <inertia ixx="1.0" ixy="0.0" ixz="0.0" iyy="0.5" iyz="0.0" izz="1.0"/>
    </inertial>
  </link>
  <joint name="joint6" type="revolute">
    <parent link="link5"/>
    <child link="link6"/>
    <origin rpy="4.712385 -1.570795 0" xyz="0 0 0.06"/>
    <axis xyz="1 0 0"/>
    <limit effort="300" lower="-6.28" upper="6.28" velocity="1"/>
    <dynamics damping="50" friction="1"/>
  </joint>
  <!-- ////////////////////////////////   LINK6  ///////////////////////////////////////////////// -->
  <link name="link6">
    <visual>
      <origin rpy="0 1.570795 0" xyz="0.01 0 0 "/>
      <geometry>
        <cylinder length="0.02" radius="0.04"/>
      </geometry>
      <material name="Blue"/>
    </visual>
    <collision>
      <origin rpy="0 1.570795 0" xyz="0.01 0 0"/>
      <geometry>
        <cylinder length="0.02" radius="0.04"/>
      </geometry>
    </collision>
    <inertial>
      <mass value="1"/>
      <inertia ixx="1.0" ixy="0.0" ixz="0.0" iyy="0.5" iyz="0.0" izz="1.0"/>
    </inertial>
  </link>
  <joint name="finger_joint1" type="prismatic">
    <parent link="link6"/>
    <child link="gripper_finger_link1"/>
    <origin xyz="0.0 0 0"/>
    <axis xyz="0 1 0"/>
    <limit effort="100" lower="0" upper="0.06" velocity="1.0"/>
    <dynamics damping="50" friction="1"/>
  </joint>
  <!-- //////////////////////////////////////   gripper   ////////////////////////////////////////////// -->
  <!-- LEFT GRIPPER AFT LINK -->
  <link name="gripper_finger_link1">
    <visual>
      <origin xyz="0.04 -0.03 0"/>
      <geometry>
        <box size="0.08 0.01 0.01"/>
      </geometry>
      <material name="White"/>
    </visual>
    <inertial>
      <mass value="1"/>
      <inertia ixx="1.0" ixy="0.0" ixz="0.0" iyy="0.5" iyz="0.0" izz="1.0"/>
    </inertial>
  </link>
  <joint name="finger_joint2" type="fixed">
    <parent link="link6"/>
    <child link="gripper_finger_link2"/>
    <origin xyz="0.0 0 0"/>
  </joint>
  <!-- RIGHT GRIPPER AFT LINK -->
  <link name="gripper_finger_link2">
    <visual>
      <origin xyz="0.04 0.03 0"/>
      <geometry>
        <box size="0.08 0.01 0.01"/>
      </geometry>
      <material name="White"/>
    </visual>
    <inertial>
      <mass value="1"/>
      <inertia ixx="1.0" ixy="0.0" ixz="0.0" iyy="0.5" iyz="0.0" izz="1.0"/>
    </inertial>
  </link>
  <!-- Grasping frame -->
  <link name="grasping_frame"/>
  <joint name="grasping_frame_joint" type="fixed">
    <parent link="link6"/>
    <child link="grasping_frame"/>
    <origin rpy="0 0 0" xyz="0.08 0 0"/>
  </joint>
</robot>

